<?xml version="1.0" encoding="UTF-8"?>
<!-- Generated by org.testng.reporters.JUnitReportReporter -->
<testsuite hostname="DVCINH6110119" failures="2" tests="10" name="failScript.failScriptExample" time="0.018" errors="0" timestamp="2025-02-12T01:55:28 IST" skipped="6">
  <testcase classname="failScript.failScriptExample" name="testMethod3" time="0.003">
    <skipped/>
  </testcase> <!-- testMethod3 -->
  <testcase classname="failScript.failScriptExample" name="testMethod1" time="0.008"/>
  <testcase classname="failScript.failScriptExample" name="testMethod4" time="0.002">
    <skipped/>
  </testcase> <!-- testMethod4 -->
  <testcase classname="failScript.failScriptExample" name="testMethod3" time="0.000">
    <skipped/>
  </testcase> <!-- testMethod3 -->
  <testcase classname="failScript.failScriptExample" name="testMethod4" time="0.000">
    <skipped/>
  </testcase> <!-- testMethod4 -->
  <testcase classname="failScript.failScriptExample" name="testMethod3" time="0.003">
    <failure message="expected [true] but found [false]" type="java.lang.AssertionError">
      <![CDATA[java.lang.AssertionError: expected [true] but found [false]
at org.testng.Assert.fail(Assert.java:111)
at org.testng.Assert.failNotEquals(Assert.java:1578)
at org.testng.Assert.assertTrue(Assert.java:57)
at org.testng.Assert.assertTrue(Assert.java:67)
at failScript.failScriptExample.testMethod3(failScriptExample.java:21)
at java.base/jdk.internal.reflect.DirectMethodHandleAccessor.invoke(DirectMethodHandleAccessor.java:103)
at java.base/java.lang.reflect.Method.invoke(Method.java:580)
at org.testng.internal.invokers.MethodInvocationHelper.invokeMethod(MethodInvocationHelper.java:141)
at org.testng.internal.invokers.TestInvoker.invokeMethod(TestInvoker.java:686)
at org.testng.internal.invokers.TestInvoker.retryFailed(TestInvoker.java:269)
at org.testng.internal.invokers.MethodRunner.runInSequence(MethodRunner.java:76)
at org.testng.internal.invokers.TestInvoker$MethodInvocationAgent.invoke(TestInvoker.java:992)
at org.testng.internal.invokers.TestInvoker.invokeTestMethods(TestInvoker.java:203)
at org.testng.internal.invokers.TestMethodWorker.invokeTestMethods(TestMethodWorker.java:154)
at org.testng.internal.invokers.TestMethodWorker.run(TestMethodWorker.java:134)
at java.base/java.util.ArrayList.forEach(ArrayList.java:1596)
at org.testng.TestRunner.privateRun(TestRunner.java:739)
at org.testng.TestRunner.run(TestRunner.java:614)
at org.testng.SuiteRunner.runTest(SuiteRunner.java:421)
at org.testng.SuiteRunner.runSequentially(SuiteRunner.java:413)
at org.testng.SuiteRunner.privateRun(SuiteRunner.java:373)
at org.testng.SuiteRunner.run(SuiteRunner.java:312)
at org.testng.SuiteRunnerWorker.runSuite(SuiteRunnerWorker.java:52)
at org.testng.SuiteRunnerWorker.run(SuiteRunnerWorker.java:95)
at org.testng.TestNG.runSuitesSequentially(TestNG.java:1274)
at org.testng.TestNG.runSuitesLocally(TestNG.java:1208)
at org.testng.TestNG.runSuites(TestNG.java:1112)
at org.testng.TestNG.run(TestNG.java:1079)
at com.intellij.rt.testng.IDEARemoteTestNG.run(IDEARemoteTestNG.java:65)
at com.intellij.rt.testng.RemoteTestNGStarter.main(RemoteTestNGStarter.java:105)
]]>
    </failure>
  </testcase> <!-- testMethod3 -->
  <testcase classname="failScript.failScriptExample" name="testMethod4" time="0.000">
    <failure message="expected [true] but found [false]" type="java.lang.AssertionError">
      <![CDATA[java.lang.AssertionError: expected [true] but found [false]
at org.testng.Assert.fail(Assert.java:111)
at org.testng.Assert.failNotEquals(Assert.java:1578)
at org.testng.Assert.assertTrue(Assert.java:57)
at org.testng.Assert.assertTrue(Assert.java:67)
at failScript.failScriptExample.testMethod4(failScriptExample.java:26)
at java.base/jdk.internal.reflect.DirectMethodHandleAccessor.invoke(DirectMethodHandleAccessor.java:103)
at java.base/java.lang.reflect.Method.invoke(Method.java:580)
at org.testng.internal.invokers.MethodInvocationHelper.invokeMethod(MethodInvocationHelper.java:141)
at org.testng.internal.invokers.TestInvoker.invokeMethod(TestInvoker.java:686)
at org.testng.internal.invokers.TestInvoker.retryFailed(TestInvoker.java:269)
at org.testng.internal.invokers.MethodRunner.runInSequence(MethodRunner.java:76)
at org.testng.internal.invokers.TestInvoker$MethodInvocationAgent.invoke(TestInvoker.java:992)
at org.testng.internal.invokers.TestInvoker.invokeTestMethods(TestInvoker.java:203)
at org.testng.internal.invokers.TestMethodWorker.invokeTestMethods(TestMethodWorker.java:154)
at org.testng.internal.invokers.TestMethodWorker.run(TestMethodWorker.java:134)
at java.base/java.util.ArrayList.forEach(ArrayList.java:1596)
at org.testng.TestRunner.privateRun(TestRunner.java:739)
at org.testng.TestRunner.run(TestRunner.java:614)
at org.testng.SuiteRunner.runTest(SuiteRunner.java:421)
at org.testng.SuiteRunner.runSequentially(SuiteRunner.java:413)
at org.testng.SuiteRunner.privateRun(SuiteRunner.java:373)
at org.testng.SuiteRunner.run(SuiteRunner.java:312)
at org.testng.SuiteRunnerWorker.runSuite(SuiteRunnerWorker.java:52)
at org.testng.SuiteRunnerWorker.run(SuiteRunnerWorker.java:95)
at org.testng.TestNG.runSuitesSequentially(TestNG.java:1274)
at org.testng.TestNG.runSuitesLocally(TestNG.java:1208)
at org.testng.TestNG.runSuites(TestNG.java:1112)
at org.testng.TestNG.run(TestNG.java:1079)
at com.intellij.rt.testng.IDEARemoteTestNG.run(IDEARemoteTestNG.java:65)
at com.intellij.rt.testng.RemoteTestNGStarter.main(RemoteTestNGStarter.java:105)
]]>
    </failure>
  </testcase> <!-- testMethod4 -->
  <testcase classname="failScript.failScriptExample" name="testMethod3" time="0.002">
    <skipped/>
  </testcase> <!-- testMethod3 -->
  <testcase classname="failScript.failScriptExample" name="testMethod4" time="0.000">
    <skipped/>
  </testcase> <!-- testMethod4 -->
  <testcase classname="failScript.failScriptExample" name="testMethod2" time="0.000"/>
</testsuite> <!-- failScript.failScriptExample -->
